Workbook

Sheet Critérios
A1: Base cruzada — Mosaico Card: Cinema & Séries
A2: Versão final de 13/10/2026 · recorte: a partir de 2001 · público-alvo 15–25 anos · REGRA DA BASE: fica o título que aparece em pelo menos 3 bases OU tem selo Geração Z, mais 21 títulos resgatados manualmente (marcados em Observações/Conferir). Os demais estão na aba Excluídos.
A4: PARÂMETROS (células amarelas; a planilha recalcula ao alterar)
A5: Bônus por selo (somado ao índice, por selo presente) | B5: 0.03
A6: Corte: sai quem fica abaixo deste percentil do índice (1/3 = terço inferior) | B6: 0.33333333
A7: Corte da faixa A (índice ≥) | B7: 0.7
A8: Corte da faixa B (índice ≥) | B8: 0.4
A9: Tamanho da seleção Sucessos (por formato) | B9: 50
A11: ÍNDICE DOS FILMES
A12: Métricas (pesos iguais): percentil do público no Brasil, percentil da bilheteria mundial e percentil dos votos no IMDb. O índice é a MÉDIA das métricas que o título tem (quem não tem uma métrica não é penalizado por ela).
A13: Selos (somam o bônus acima, cada um): Letterboxd (populares/mais bem avaliados do ano ou de todos os tempos), JustWatch Brasil (populares hoje), Nielsen (tops anuais de streaming de filmes), Whip Media (top 10 semanal), Geração Z (YPulse/UCLA/Morning Consult), Parrot Analytics (alta demanda no Brasil).
A14: ÍNDICE DAS SÉRIES
A15: Métricas (pesos iguais): percentil dos votos no IMDb e "audiência oficial" = a melhor pontuação entre: Netflix Top 10 histórico (1 − (posição−1)/20), ranking Nielsen (1 − (posição−1)/(2 × tamanho da lista); TV aberta 2001–2020 com lista de 40, streaming 2020–2025 com lista de 30) e média de audiência por temporada (0,5 + 0,5 × percentil). Estar num ranking oficial já vale de 0,5 a 1.
A16: Nº de bases: cada fonte em que o título aparece conta 1 (filmes: público BR, bilheteria mundial, IMDb, Letterboxd, JustWatch, Nielsen, Whip, Geração Z, Parrot; séries: IMDb, audiência oficial coletada, Nielsen, Geração Z, Parrot, Whip, JustWatch).
A17: Selos (bônus): Geração Z, Parrot Analytics (Brasil), Whip Media, JustWatch Brasil. A Nielsen entra como métrica, não como selo, para não contar duas vezes.
A19: FAIXAS
A20: Percentis, índice e faixas são recalculados só entre os títulos da base final. Faixa A ≥ corte A; B ≥ corte B; C abaixo. A coluna informativa de terço inferior não exclui nada: "Sairia — terço inferior" se o índice estiver abaixo do percentil definido acima, calculado separadamente para filmes e para séries; "Sairia — sem métrica" se o título não tiver nenhuma métrica.
A22: ORIGEM DOS TÍTULOS
A23: Bilheteria (Ancine/Wikipédia): base original de filmes. Audiência oficial (coleta) / Curadoria: base original de séries. "Adicionado por: …": título que não estava na base e entrou porque apareceu numa das novas fontes (Letterboxd, JustWatch, Nielsen, Whip, Parrot, Geração Z), sempre lançado de 2001 em diante e excluídos realities, esportes, noticiários e programas de auditório.
A25: CUIDADOS
... A37: Status (amarelo): candidato → selecionado → em escrita → aprovado, ou excluído. Filtre por "Corte (prévia)" para revisar quem sairia antes de excluir.

Sheet Resumo
A1: Resumo da base final
A3: FILMES
A4: Total | B4: =COUNTA(Filmes!A2:A354) -> 353
A5: Faixa A | B5: =COUNTIF(Filmes!Y2:Y354,"A") -> 71
A6: Faixa B | B6: =COUNTIF(Filmes!Y2:Y354,"B") -> 163
A7: Faixa C | B7: =COUNTIF(Filmes!Y2:Y354,"C") -> 119
A8: Nacionais | B8: =COUNTIF(Filmes!E2:E354,"Sim") -> 7
A9: Com 3 métricas | B9: =COUNTIF(Filmes!P2:P354,3) -> 230
A10: Com ao menos 1 selo | B10: =COUNTIF(Filmes!W2:W354,">0") -> 197
A11: Adicionados pelas novas fontes | B11: =COUNTIF(Filmes!F2:F354,"Adicionado*") -> 39
A12: SÉRIES
A13: Total | B13: =COUNTA(Séries!A2:A85) -> 84
A14: Faixa A | B14: =COUNTIF(Séries!AB2:AB85,"A") -> 39
A15: Faixa B | B15: =COUNTIF(Séries!AB2:AB85,"B") -> 32
A16: Faixa C | B16: =COUNTIF(Séries!AB2:AB85,"C") -> 13
A17: Com audiência oficial | B17: =COUNT(Séries!T2:T85) -> 55
A18: Com ao menos 1 selo | B18: =COUNTIF(Séries!Z2:Z85,">0") -> 75
A19: Adicionadas pelas novas fontes | B19: =COUNTIF(Séries!F2:F85,"Adicionado*") -> 26
A20: TOTAL NA BASE FINAL | B20: =B4+B13 -> 437
A21: Excluídos (aba Excluídos) | B21: =COUNTA(Excluídos!A2:A1428) -> 1427
A22: Mantidos só pelo selo Geração Z (filmes/séries) | B22: 0 / 7
A23: Seleção Sucessos — filmes | B23: =COUNTIF(Filmes!AJ2:AJ354,"Sim") -> 50
A24: Seleção Sucessos — séries | B24: =COUNTIF(Séries!AN2:AN85,"Sim") -> 50
A25: Resgatados manualmente (filmes/séries) | B25: 11 / 10

Sheet Filmes
A1: ID | B1: Título no Brasil | C1: Título original | D1: Ano | E1: Nacional | F1: Origem na base | G1: Público no Brasil | H1: Renda no Brasil (R$) | I1: Bilheteria mundial (US$) | J1: Posição mundial no ano | K1: Votos no IMDb | L1: Nota IMDb | M1: Percentil público BR | N1: Percentil bilheteria mundial | O1: Percentil votos IMDb | P1: Nº de métricas | Q1: Selo Letterboxd | R1: Selo JustWatch BR | S1: Selo Nielsen | T1: Selo Whip Media | U1: Selo Geração Z | V1: Selo Parrot BR | W1: Nº de selos | X1: Índice | Y1: Faixa | Z1: Posição | AA1: Terço inferior da base final (informativo) | AB1: Protagonista (preliminar) | AC1: Observações | AD1: Status | AE1: Notas editoriais | AF1: Fontes | AG1: IMDb ID | AH1: Nº de bases em que aparece | AI1: Presente em ≥3 bases | AJ1: Seleção Sucessos
A2: F0001 | B2: Vingadores: Ultimato | C2: Avengers: Endgame | D2: 2019 | E2: Não | F2: Bilheteria (Ancine/Wikipédia) | G2: 19656475 | H2: 338624955 | I2: 2799439100 | J2: 1 | K2: 1499173 | L2: 8.4 | M2: =IF(G2="","",PERCENTRANK($G$2:$G$354,G2)) -> 0.997 | N2: =IF(I2="","",PERCENTRANK($I$2:$I$354,I2)) -> 1 | O2: =IF(K2="","",PERCENTRANK($K$2:$K$354,K2)) -> 0.966 | P2: =COUNT(M2:O2) -> 3 | Q2: 2019 populares #1 | W2: =COUNTA(Q2:V2) -> 1 | X2: =IF(P2=0,"",MIN(1,AVERAGE(M2:O2)+Critérios!$B$5*W2)) -> 1 | Y2: =IF(X2="","",IF(X2>=Critérios!$B$7,"A",IF(X2>=Critérios!$B$8,"B","C"))) -> A | Z2: =IF(X2="","",RANK(X2,$X$2:$X$354)) -> 1 | AA2: =IF(X2="","Sairia — sem métrica",IF(PERCENTRANK($X$2:$X$354,X2)<Critérios!$B$6,"Sairia — terço inferior","Fica")) -> Fica | AB2: ambíguo (provável) — conferir | AD2: candidato | AF2: S052, S192, S201, S208 | AG2: tt4154796 | AH2: =COUNT(G2,I2,K2)+COUNTA(Q2:V2) -> 4 | AI2: =IF(AH2>=3,"Sim","Não") -> Sim | AJ2: =IF(AND(Z2<>"",Z2<=Critérios!$B$9),"Sim","Não") -> Sim
A3: F0002 | B3: Homem-Aranha: Sem Volta para Casa | C3: Spider-Man: No Way Home | D3: 2021 | E3: Não | F3: Bilheteria (Ancine/Wikipédia) | G3: 16614010 | H3: 307392631 | I3: 1921426073 | J3: 1 | K3: 1081111 | L3: 8.1 | M3: =IF(G3="","",PERCENTRANK($G$2:$G$354,G3)) -> 0.99 | N3: =IF(I3="","",PERCENTRANK($I$2:$I$354,I3)) -> 0.97 | O3: =IF(K3="","",PERCENTRANK($K$2:$K$354,K3)) -> 0.912 | P3: =COUNT(M3:O3) -> 3 | Q3: 2021 populares #2; 2021 mais bem avaliados #1 | R3: #43 hoje | T3: 15–17 jul 2022 #9 (United States); 22–24 jul 2022 #8 (United States) | W3: =COUNTA(Q3:V3) -> 3 | X3: =IF(P3=0,"",MIN(1,AVERAGE(M3:O3)+Critérios!$B$5*W3)) -> 1 | Y3: =IF(X3="","",IF(X3>=Critérios!$B$7,"A",IF(X3>=Critérios!$B$8,"B","C"))) -> A | Z3: =IF(X3="","",RANK(X3,$X$2:$X$354)) -> 1 | AA3: =IF(X3="","Sairia — sem métrica",IF(PERCENTRANK($X$2:$X$354,X3)<Critérios!$B$6,"Sairia — terço inferior","Fica")) -> Fica | AB3: a avaliar | AD3: candidato | AF3: S054, S192, S199, S200, S201 | AG3: tt10872600 | AH3: =COUNT(G3,I3,K3)+COUNTA(Q3:V3) -> 6 | AI3: =IF(AH3>=3,"Sim","Não") -> Sim | AJ3: =IF(AND(Z3<>"",Z3<=Critérios!$B$9),"Sim","Não") -> Sim
A4: F0003 | B4: Vingadores: Guerra Infinita | C4: Avengers: Infinity War | D4: 2018 | E4: Não | F4: Bilheteria (Ancine/Wikipédia) | G4: 14502151 | H4: 238029913 | I4: 2048359754 | J4: 1 | K4: 1417008 | L4: 8.4 | M4: =IF(G4="","",PERCENTRANK($G$2:$G$354,G4)) -> 0.984 | N4: =IF(I4="","",PERCENTRANK($I$2:$I$354,I4)) -> 0.975 | O4: =IF(K4="","",PERCENTRANK($K$2:$K$354,K4)) -> 0.963 | P4: =COUNT(M4:O4) -> 3 | Q4: 2018 populares #2; 2018 mais bem avaliados #13 | W4: =COUNTA(Q4:V4) -> 1 | X4: =IF(P4=0,"",MIN(1,AVERAGE(M4:O4)+Critérios!$B$5*W4)) -> 1 | Y4: =IF(X4="","",IF(X4>=Critérios!$B$7,"A",IF(X4>=Critérios!$B$8,"B","C"))) -> A | Z4: =IF(X4="","",RANK(X4,$X$2:$X$354)) -> 1 | AA4: =IF(X4="","Sairia — sem métrica",IF(PERCENTRANK($X$2:$X$354,X4)<Critérios!$B$6,"Sairia — terço inferior","Fica")) -> Fica | AB4: ambíguo (provável) — conferir | AD4: candidato | AF4: S051, S191, S192, S201 | AG4: tt4154756 | AH4: =COUNT(G4,I4,K4)+COUNTA(Q4:V4) -> 4 | AI4: =IF(AH4>=3,"Sim","Não") -> Sim | AJ4: =IF(AND(Z4<>"",Z4<=Critérios!$B$9),"Sim","Não") -> Sim
A5: F0004 | B5: Avatar: O Caminho da Água | C5: Avatar: The Way of Water | D5: 2022 | E5: Não | F5: Bilheteria (Ancine/Wikipédia) | G5: 11551730 | H5: 240271275 | I5: 2320250281 | J5: 1 | K5: 649893 | L5: 7.5 | M5: =IF(G5="","",PERCENTRANK($G$2:$G$354,G5)) -> 0.98 | N5: =IF(I5="","",PERCENTRANK($I$2:$I$354,I5)) -> 0.987 | O5: =IF(K5="","",PERCENTRANK($K$2:$K$354,K5)) -> 0.696 | P5: =COUNT(M5:O5) -> 3 | Q5: 2022 populares #16 | S5: 2023 #9 | T5: 16–18 jun 2023 #3 (United States) | W5: =COUNTA(Q5:V5) -> 3 | X5: =IF(P5=0,"",MIN(1,AVERAGE(M5:O5)+Critérios!$B$5*W5)) -> 0.97766667 | Y5: =IF(X5="","",IF(X5>=Critérios!$B$7,"A",IF(X5>=Critérios!$B$8,"B","C"))) -> A | Z5: =IF(X5="","",RANK(X5,$X$2:$X$354)) -> 4 | AA5: =IF(X5="","Sairia — sem métrica",IF(PERCENTRANK($X$2:$X$354,X5)<Critérios!$B$6,"Sairia — terço inferior","Fica")) -> Fica | AB5: a avaliar | AD5: candidato | AF5: S055, S192, S200, S201 | AG5: tt1630029 | AH5: =COUNT(G5,I5,K5)+COUNTA(Q5:V5) -> 6 | AI5: =IF(AH5>=3,"Sim","Não") -> Sim | AJ5: =IF(AND(Z5<>"",Z5<=Critérios!$B$9),"Sim","Não") -> Sim
A6: F0005 | B6: V de Vingança | C6: V for Vendetta | D6: 2005 | E6: Não | F6: Adicionado por: JustWatch Brasil | K6: 1258464 | L6: 8.1 | M6: =IF(G6="","",PERCENTRANK($G$2:$G$354,G6)) | N6: =IF(I6="","",PERCENTRANK($I$2:$I$354,I6)) | O6: =IF(K6="","",PERCENTRANK($K$2:$K$354,K6)) -> 0.943 | P6: =COUNT(M6:O6) -> 1 | R6: #71 hoje | W6: =COUNTA(Q6:V6) -> 1 | X6: =IF(P6=0,"",MIN(1,AVERAGE(M6:O6)+Critérios!$B$5*W6)) -> 0.973 | Y6: =IF(X6="","",IF(X6>=Critérios!$B$7,"A",IF(X6>=Critérios!$B$8,"B","C"))) -> A | Z6: =IF(X6="","",RANK(X6,$X$2:$X$354)) -> 5 | AA6: =IF(X6="","Sairia — sem métrica",IF(PERCENTRANK($X$2:$X$354,X6)<Critérios!$B$6,"Sairia — terço inferior","Fica")) -> Fica | AB6: a avaliar | AC6: Resgatado manualmente (lista aprovada em 13/10/2026) | AD6: candidato | AG6: tt0434409 | AH6: =COUNT(G6,I6,K6)+COUNTA(Q6:V6) -> 2 | AI6: =IF(AH6>=3,"Sim","Não") -> Não | AJ6: =IF(AND(Z6<>"",Z6<=Critérios!$B$9),"Sim","Não") -> Sim
A7: F0006 | B7: Avatar | C7: Avatar | D7: 2009 | E7: Não | F7: Bilheteria (Ancine/Wikipédia) | G7: 9111628 | H7: 102346712 | I7: 2743577587 | J7: 1 | K7: 1518568 | L7: 7.9 | M7: =IF(G7="","",PERCENTRANK($G$2:$G$354,G7)) -> 0.944 | N7: =IF(I7="","",PERCENTRANK($I$2:$I$354,I7)) -> 0.996 | O7: =IF(K7="","",PERCENTRANK($K$2:$K$354,K7)) -> 0.969 | P7: =COUNT(M7:O7) -> 3 | W7: =COUNTA(Q7:V7) -> 0 | X7: =IF(P7=0,"",MIN(1,AVERAGE(M7:O7)+Critérios!$B$5*W7)) -> 0.96966667 | Y7: =IF(X7="","",IF(X7>=Critérios!$B$7,"A",IF(X7>=Critérios!$B$8,"B","C"))) -> A | Z7: =IF(X7="","",RANK(X7,$X$2:$X$354)) -> 6 | AA7: =IF(X7="","Sairia — sem métrica",IF(PERCENTRANK($X$2:$X$354,X7)<Critérios!$B$6,"Sairia — terço inferior","Fica")) -> Fica | AB7: a avaliar | AD7: candidato | AF7: S042, S191, S197 | AG7: tt0499549 | AH7: =COUNT(G7,I7,K7)+COUNTA(Q7:V7) -> 3 | AI7: =IF(AH7>=3,"Sim","Não") -> Sim | AJ7: =IF(AND(Z7<>"",Z7<=Critérios!$B$9),"Sim","Não") -> Sim
A8: F0007 | B8: Os Vingadores | C8: The Avengers | D8: 2012 | E8: Não | F8: Bilheteria (Ancine/Wikipédia) | G8: 10911371 | H8: 129595590 | I8: 1518812988 | J8: 1 | K8: 1587532 | L8: 8 | M8: =IF(G8="","",PERCENTRANK($G$2:$G$354,G8)) -> 0.977 | N8: =IF(I8="","",PERCENTRANK($I$2:$I$354,I8)) -> 0.945 | O8: =IF(K8="","",PERCENTRANK($K$2:$K$354,K8)) -> 0.974 | P8: =COUNT(M8:O8) -> 3 | W8: =COUNTA(Q8:V8) -> 0 | X8: =IF(P8=0,"",MIN(1,AVERAGE(M8:O8)+Critérios!$B$5*W8)) -> 0.96533333 | Y8: =IF(X8="","",IF(X8>=Critérios!$B$7,"A",IF(X8>=Critérios!$B$8,"B","C"))) -> A | Z8: =IF(X8="","",RANK(X8,$X$2:$X$354)) -> 7 | AA8: =IF(X8="","Sairia — sem métrica",IF(PERCENTRANK($X$2:$X$354,X8)<Critérios!$B$6,"Sairia — terço inferior","Fica")) -> Fica | AB8: ambíguo (provável) — conferir | AD8: candidato | AF8: S045, S191, S205 | AG8: tt0848228 | AH8: =COUNT(G8,I8,K8)+COUNTA(Q8:V8) -> 3 | AI8: =IF(AH8>=3,"Sim","Não") -> Sim | AJ8: =IF(AND(Z8<>"",Z8<=Critérios!$B$9),"Sim","Não") -> Sim
A9: F0008 | B9: Onde os Fracos Não Têm Vez | C9: No Country for Old Men | D9: 2007 | E9: Não | F9: Adicionado por: JustWatch Brasil | K9: 1217854 | L9: 8.2 | M9: =IF(G9="","",PERCENTRANK($G$2:$G$354,G9)) | N9: =IF(I9="","",PERCENTRANK($I$2:$I$354,I9)) | O9: =IF(K9="","",PERCENTRANK($K$2:$K$354,K9)) -> 0.935 | P9: =COUNT(M9:O9) -> 1 | R9: #98 hoje | W9: =COUNTA(Q9:V9) -> 1 | X9: =IF(P9=0,"",MIN(1,AVERAGE(M9:O9)+Critérios!$B$5*W9)) -> 0.965 | Y9: =IF(X9="","",IF(X9>=Critérios!$B$7,"A",IF(X9>=Critérios!$B$8,"B","C"))) -> A | Z9: =IF(X9="","",RANK(X9,$X$2:$X$354)) -> 8 | AA9: =IF(X9="","Sairia — sem métrica",IF(PERCENTRANK($X$2:$X$354,X9)<Critérios!$B$6,"Sairia — terço inferior","Fica")) -> Fica | AB9: a avaliar | AC9: Resgatado manualmente (lista aprovada em 13/10/2026) | AD9: candidato | AG9: tt0477348 | AH9: =COUNT(G9,I9,K9)+COUNTA(Q9:V9) -> 2 | AI9: =IF(AH9>=3,"Sim","Não") -> Não | AJ9: =IF(AND(Z9<>"",Z9<=Critérios!$B$9),"Sim","Não") -> Sim
A10: F0009 | B10: Brilho Eterno de uma Mente sem Lembranças | C10: Eternal Sunshine of the Spotless Mind | D10: 2004 | E10: Não | F10: Adicionado por: JustWatch Brasil | K10: 1199281 | L10: 8.3 | M10: =IF(G10="","",PERCENTRANK($G$2:$G$354,G10)) | N10: =IF(I10="","",PERCENTRANK($I$2:$I$354,I10)) | O10: =IF(K10="","",PERCENTRANK($K$2:$K$354,K10)) -> 0.929 | P10: =COUNT(M10:O10) -> 1 | R10: #129 hoje | W10: =COUNTA(Q10:V10) -> 1 | X10: =IF(P10=0,"",MIN(1,AVERAGE(M10:O10)+Critérios!$B$5*W10)) -> 0.959 | Y10: =IF(X10="","",IF(X10>=Critérios!$B$7,"A",IF(X10>=Critérios!$B$8,"B","C"))) -> A | Z10: =IF(X10="","",RANK(X10,$X$2:$X$354)) -> 9 | AA10: =IF(X10="","Sairia — sem métrica",IF(PERCENTRANK($X$2:$X$354,X10)<Critérios!$B$6,"Sairia — terço inferior","Fica")) -> Fica | AB10: a avaliar | AC10: Resgatado manualmente (lista aprovada em 13/10/2026) | AD10: candidato | AG10: tt0338013 | AH10: =COUNT(G10,I10,K10)+COUNTA(Q10:V10) -> 2 | AI10: =IF(AH10>=3,"Sim","Não") -> Não | AJ10: =IF(AND(Z10<>"",Z10<=Critérios!$B$9),"Sim","Não") -> Sim
A11: F0010 | B11: Garota Exemplar | C11: Gone Girl | D11: 2014 | E11: Não | F11: Adicionado por: JustWatch Brasil | K11: 1191566 | L11: 8.1 | M11: =IF(G11="","",PERCENTRANK($G$2:$G$354,G11)) | N11: =IF(I11="","",PERCENTRANK($I$2:$I$354,I11)) | O11: =IF(K11="","",PERCENTRANK($K$2:$K$354,K11)) -> 0.926 | P11: =COUNT(M11:O11) -> 1 | R11: #106 hoje | W11: =COUNTA(Q11:V11) -> 1 | X11: =IF(P11=0,"",MIN(1,AVERAGE(M11:O11)+Critérios!$B$5*W11)) -> 0.956 | Y11: =IF(X11="","",IF(X11>=Critérios!$B$7,"A",IF(X11>=Critérios!$B$8,"B","C"))) -> A | Z11: =IF(X11="","",RANK(X11,$X$2:$X$354)) -> 10 | AA11: =IF(X11="","Sairia — sem métrica",IF(PERCENTRANK($X$2:$X$354,X11)<Critérios!$B$6,"Sairia — terço inferior","Fica")) -> Fica | AB11: a avaliar | AC11: Resgatado manualmente (lista aprovada em 13/10/2026) | AD11: candidato | AG11: tt2267998 | AH11: =COUNT(G11,I11,K11)+COUNTA(Q11:V11) -> 2 | AI11: =IF(AH11>=3,"Sim","Não") -> Não | AJ11: =IF(AND(Z11<>"",Z11<=Critérios!$B$9),"Sim","Não") -> Sim
A12: F0011 | B12: Coringa | C12: Joker | D12: 2019 | E12: Não | F12: Bilheteria (Ancine/Wikipédia) | G12: 9766507 | H12: 157153605 | I12: 1079751311 | J12: 6 | K12: 1730798 | L12: 8.3 | M12: =IF(G12="","",PERCENTRANK($G$2:$G$354,G12)) -> 0.958 | N12: =IF(I12="","",PERCENTRANK($I$2:$I$354,I12)) -> 0.822 | O12: =IF(K12="","",PERCENTRANK($K$2:$K$354,K12)) -> 0.977 | P12: =COUNT(M12:O12) -> 3 | Q12: 2019 populares #2; populares de todos os tempos #5; populares de todos os tempos #2; populares de todos os tempos #6 | W12: =COUNTA(Q12:V12) -> 1 | X12: =IF(P12=0,"",MIN(1,AVERAGE(M12:O12)+Critérios!$B$5*W12)) -> 0.949 | Y12: =IF(X12="","",IF(X12>=Critérios!$B$7,"A",IF(X12>=Critérios!$B$8,"B","C"))) -> A | Z12: =IF(X12="","",RANK(X12,$X$2:$X$354)) -> 11 | AA12: =IF(X12="","Sairia — sem métrica",IF(PERCENTRANK($X$2:$X$354,X12)<Critérios!$B$6,"Sairia — terço inferior","Fica")) -> Fica | AB12: a avaliar | AD12: candidato | AF12: S052, S192, S201, S208 | AG12: tt7286456 | AH12: =COUNT(G12,I12,K12)+COUNTA(Q12:V12) -> 4 | AI12: =IF(AH12>=3,"Sim","Não") -> Sim | AJ12: =IF(AND(Z12<>"",Z12<=Critérios!$B$9),"Sim","Não") -> Sim
A13: F0012 | B13: Era Uma Vez em... Hollywood | C13: Once Upon a Time in... Hollywood | D13: 2019 | E13: Não | F13: Adicionado por: Letterboxd | K13: 982180 | L13: 7.6 | M13: =IF(G13="","",PERCENTRANK($G$2:$G$354,G13)) | N13: =IF(I13="","",PERCENTRANK($I$2:$I$354,I13)) | O13: =IF(K13="","",PERCENTRANK($K$2:$K$354,K13)) -> 0.881 | P13: =COUNT(M13:O13) -> 1 | Q13: 2019 populares #3 | R13: #103 hoje | W13: =COUNTA(Q13:V13) -> 2 | X13: =IF(P13=0,"",MIN(1,AVERAGE(M13:O13)+Critérios!$B$5*W13)) -> 0.941 | Y13: =IF(X13="","",IF(X13>=Critérios!$B$7,"A",IF(X13>=Critérios!$B$8,"B","C"))) -> A | Z13: =IF(X13="","",RANK(X13,$X$2:$X$354)) -> 12 | AA13: =IF(X13="","Sairia — sem métrica",IF(PERCENTRANK($X$2:$X$354,X13)<Critérios!$B$6,"Sairia — terço inferior","Fica")) -> Fica | AB13: a avaliar | AD13: candidato | AG13: tt7131622 | AH13: =COUNT(G13,I13,K13)+COUNTA(Q13:V13) -> 3 | AI13: =IF(AH13>=3,"Sim","Não") -> Sim | AJ13: =IF(AND(Z13<>"",Z13<=Critérios!$B$9),"Sim","Não") -> Sim
A14: F0013 | B14: Barbie | C14: Barbie | D14: 2023 | E14: Não | F14: Bilheteria (Ancine/Wikipédia) | G14: 10679592 | H14: 207205705 | I14: 1448232531 | J14: 1 | K14: 708172 | L14: 6.8 | M14: =IF(G14="","",PERCENTRANK($G$2:$G$354,G14)) -> 0.974 | N14: =IF(I14="","",PERCENTRANK($I$2:$I$354,I14)) -> 0.924 | O14: =IF(K14="","",PERCENTRANK($K$2:$K$354,K14)) -> 0.727 | P14: =COUNT(M14:O14) -> 3 | Q14: 2023 populares #1; populares de todos os tempos #1; populares de todos os tempos #4 | U14: UCLA Teens & Screens 2023 2023-10 (10-24) | W14: =COUNTA(Q14:V14) -> 2 | X14: =IF(P14=0,"",MIN(1,AVERAGE(M14:O14)+Critérios!$B$5*W14)) -> 0.935 | Y14: =IF(X14="","",IF(X14>=Critérios!$B$7,"A",IF(X14>=Critérios!$B$8,"B","C"))) -> A | Z14: =IF(X14="","",RANK(X14,$X$2:$X$354)) -> 13 | AA14: =IF(X14="","Sairia — sem métrica",IF(PERCENTRANK($X$2:$X$354,X14)<Critérios!$B$6,"Sairia — terço inferior","Fica")) -> Fica | AB14: a avaliar | AD14: candidato | AF14: S056, S192, S201 | AG14: tt1517268 | AH14: =COUNT(G14,I14,K14)+COUNTA(Q14:V14) -> 5 | AI14: =IF(AH14>=3,"Sim","Não") -> Sim | AJ14: =IF(AND(Z14<>"",Z14<=Critérios!$B$9),"Sim","Não") -> Sim
A15: F0014 | B15: Vingadores: A Era de Ultron | C15: Avengers: Age of Ultron | D15: 2015 | E15: Não | F15: Bilheteria (Ancine/Wikipédia) | G15: 10130740 | H15: 146203313 | I15: 1402809540 | J15: 4 | K15: 1026043 | L15: 7.3 | M15: =IF(G15="","",PERCENTRANK($G$2:$G$354,G15)) -> 0.967 | N15: =IF(I15="","",PERCENTRANK($I$2:$I$354,I15)) -> 0.919 | O15: =IF(K15="","",PERCENTRANK($K$2:$K$354,K15)) -> 0.901 | P15: =COUNT(M15:O15) -> 3 | W15: =COUNTA(Q15:V15) -> 0 | X15: =IF(P15=0,"",MIN(1,AVERAGE(M15:O15)+Critérios!$B$5*W15)) -> 0.929 | Y15: =IF(X15="","",IF(X15>=Critérios!$B$7,"A",IF(X15>=Critérios!$B$8,"B","C"))) -> A | Z15: =IF(X15="","",RANK(X15,$X$2:$X$354)) -> 14 | AA15: =IF(X15="","Sairia — sem métrica",IF(PERCENTRANK($X$2:$X$354,X15)<Critérios!$B$6,"Sairia — terço inferior","Fica")) -> Fica | AB15: ambíguo (provável) — conferir | AD15: candidato | AF15: S048, S191, S192, S201, S202 | AG15: tt2395427 | AH15: =COUNT(G15,I15,K15)+COUNTA(Q15:V15) -> 3 | AI15: =IF(AH15>=3,"Sim","Não") -> Sim | AJ15: =IF(AND(Z15<>"",Z15<=Critérios!$B$9),"Sim","Não") -> Sim
A16: F0015 | B16: Capitão América: Guerra civil | C16: Captain America: Civil War | D16: 2016 | E16: Não | F16: Bilheteria (Ancine/Wikipédia) | G16: 9617668 | H16: 143337776 | I16: 1153296293 | J16: 1 | K16: 953097 | L16: 7.8 | M16: =IF(G16="","",PERCENTRANK($G$2:$G$354,G16)) -> 0.954 | N16: =IF(I16="","",PERCENTRANK($I$2:$I$354,I16)) -> 0.864 | O16: =IF(K16="","",PERCENTRANK($K$2:$K$354,K16)) -> 0.866 | P16: =COUNT(M16:O16) -> 3 | Q16: 2016 populares #2 | W16: =COUNTA(Q16:V16) -> 1 | X16: =IF(P16=0,"",MIN(1,AVERAGE(M16:O16)+Critérios!$B$5*W16)) -> 0.92466667 | Y16: =IF(X16="","",IF(X16>=Critérios!$B$7,"A",IF(X16>=Critérios!$B$8,"B","C"))) -> A | Z16: =IF(X16="","",RANK(X16,$X$2:$X$354)) -> 15 | AA16: =IF(X16="","Sairia — sem métrica",IF(PERCENTRANK($X$2:$X$354,X16)<Critérios!$B$6,"Sairia — terço inferior","Fica")) -> Fica | AB16: a avaliar | AD16: candidato | AF16: S049, S191, S192, S201, S207 | AG16: tt3498820 | AH16: =COUNT(G16,I16,K16)+COUNTA(Q16:V16) -> 4 | AI16: =IF(AH16>=3,"Sim","Não") -> Sim | AJ16: =IF(AND(Z16<>"",Z16<=Critérios!$B$9),"Sim","Não") -> Sim
A17: F0016 | B17: Pantera Negra | C17: Black Panther | D17: 2018 | E17: Não | F17: Bilheteria (Ancine/Wikipédia) | G17: 7438252 | H17: 120998283 | I17: 1347597973 | J17: 2 | K17: 929481 | L17: 7.3 | M17: =IF(G17="","",PERCENTRANK($G$2:$G$354,G17)) -> 0.873 | N17: =IF(I17="","",PERCENTRANK($I$2:$I$354,I17)) -> 0.911 | O17: =IF(K17="","",PERCENTRANK($K$2:$K$354,K17)) -> 0.849 | P17: =COUNT(M17:O17) -> 3 | Q17: 2018 populares #1 | W17: =COUNTA(Q17:V17) -> 1 | X17: =IF(P17=0,"",MIN(1,AVERAGE(M17:O17)+Critérios!$B$5*W17)) -> 0.90766667 | Y17: =IF(X17="","",IF(X17>=Critérios!$B$7,"A",IF(X17>=Critérios!$B$8,"B","C"))) -> A | Z17: =IF(X17="","",RANK(X17,$X$2:$X$354)) -> 16 | AA17: =IF(X17="","Sairia — sem métrica",IF(PERCENTRANK($X$2:$X$354,X17)<Critérios!$B$6,"Sairia — terço inferior","Fica")) -> Fica | AB17: a avaliar | AD17: candidato | AF17: S051, S191 | AG17: tt1825683 | AH17: =COUNT(G17,I17,K17)+COUNTA(Q17:V17) -> 4 | AI17: =IF(AH17>=3,"Sim","Não") -> Sim | AJ17: =IF(AND(Z17<>"",Z17<=Critérios!$B$9),"Sim","Não") -> Sim
A18: F0017 | B18: Homem de ferro 3 | C18: Iron Man 3 | D18: 2013 | E18: Não | F18: Bilheteria (Ancine/Wikipédia) | G18: 7633472 | H18: 96488326 | I18: 1214811252 | J18: 2 | K18: 987286 | L18: 7.1 | M18: =IF(G18="","",PERCENTRANK($G$2:$G$354,G18)) -> 0.879 | N18: =IF(I18="","",PERCENTRANK($I$2:$I$354,I18)) -> 0.873 | O18: =IF(K18="","",PERCENTRANK($K$2:$K$354,K18)) -> 0.886 | P18: =COUNT(M18:O18) -> 3 | W18: =COUNTA(Q18:V18) -> 0 | X18: =IF(P18=0,"",MIN(1,AVERAGE(M18:O18)+Critérios!$B$5*W18)) -> 0.87933333 | Y18: =IF(X18="","",IF(X18>=Critérios!$B$7,"A",IF(X18>=Critérios!$B$8,"B","C"))) -> A | Z18: =IF(X18="","",RANK(X18,$X$2:$X$354)) -> 17 | AA18: =IF(X18="","Sairia — sem métrica",IF(PERCENTRANK($X$2:$X$354,X18)<Critérios!$B$6,"Sairia — terço inferior","Fica")) -> Fica | AB18: a avaliar | AD18: candidato | AF18: S046, S193 | AG18: tt1300854 | AH18: =COUNT(G18,I18,K18)+COUNTA(Q18:V18) -> 3 | AI18: =IF(AH18>=3,"Sim","Não") -> Sim | AJ18: =IF(AND(Z18<>"",Z18<=Critérios!$B$9),"Sim","Não") -> Sim
A19: F0018 | B19: Logan | D19: 2017 | E19: Não | F19: Bilheteria (Ancine/Wikipédia) | G19: 6400985 | H19: 91260487 | K19: 943654 | L19: 8.1 | M19: =IF(G19="","",PERCENTRANK($G$2:$G$354,G19)) -> 0.83 | N19: =IF(I19="","",PERCENTRANK($I$2:$I$354,I19)) | O19: =IF(K19="","",PERCENTRANK($K$2:$K$354,K19)) -> 0.861 | P19: =COUNT(M19:O19) -> 2 | Q19: 2017 populares #3; 2017 mais bem avaliados #10 | W19: =COUNTA(Q19:V19) -> 1 | X19: =IF(P19=0,"",MIN(1,AVERAGE(M19:O19)+Critérios!$B$5*W19)) -> 0.8755 | Y19: =IF(X19="","",IF(X19>=Critérios!$B$7,"A",IF(X19>=Critérios!$B$8,"B","C"))) -> A | Z19: =IF(X19="","",RANK(X19,$X$2:$X$354)) -> 18 | AA19: =IF(X19="","Sairia — sem métrica",IF(PERCENTRANK($X$2:$X$354,X19)<Critérios!$B$6,"Sairia — terço inferior","Fica")) -> Fica | AB19: a avaliar | AD19: candidato | AF19: S203 | AG19: tt3315342 | AH19: =COUNT(G19,I19,K19)+COUNTA(Q19:V19) -> 3 | AI19: =IF(AH19>=3,"Sim","Não") -> Sim | AJ19: =IF(AND(Z19<>"",Z19<=Critérios!$B$9),"Sim","Não") -> Sim
A20: F0019 | B20: Harry Potter e as Reliquias da Morte: Parte 2 | C20: Harry Potter and the Deathly Hallows – Part 2 | D20: 2011 | E20: Não | F20: Bilheteria (Ancine/Wikipédia) | G20: 5577582 | H20: 57145553 | I20: 1341511219 | J20: 1 | K20: 1065924 | L20: 8.1 | M20: =IF(G20="","",PERCENTRANK($G$2:$G$354,G20)) -> 0.778 | N20: =IF(I20="","",PERCENTRANK($I$2:$I$354,I20)) -> 0.907 | O20: =IF(K20="","",PERCENTRANK($K$2:$K$354,K20)) -> 0.906 | P20: =COUNT(M20:O20) -> 3 | W20: =COUNTA(Q20:V20) -> 0 | X20: =IF(P20=0,"",MIN(1,AVERAGE(M20:O20)+Critérios!$B$5*W20)) -> 0.86366667 | Y20: =IF(X20="","",IF(X20>=Critérios!$B$7,"A",IF(X20>=Critérios!$B$8,"B","C"))) -> A | Z20: =IF(X20="","",RANK(X20,$X$2:$X$354)) -> 19 | AA20: =IF(X20="","Sairia — sem métrica",IF(PERCENTRANK($X$2:$X$354,X20)<Critérios!$B$6,"Sairia — terço inferior","Fica")) -> Fica | AB20: a avaliar | AD20: candidato | AF20: S044, S187 | AG20: tt1201607 | AH20: =COUNT(G20,I20,K20)+COUNTA(Q20:V20) -> 3 | AI20: =IF(AH20>=3,"Sim","Não") -> Sim | AJ20: =IF(AND(Z20<>"",Z20<=Critérios!$B$9),"Sim","Não") -> Sim
A21: F0020 | B21: Top Gun: Maverick | C21: Top Gun: Maverick | D21: 2022 | E21: Não | F21: Bilheteria (Ancine/Wikipédia) | G21: 5006094 | H21: 110317368 | I21: 1495696292 | J21: 2 | K21: 909213 | L21: 8.2 | M21: =IF(G21="","",PERCENTRANK($G$2:$G$354,G21)) -> 0.725 | N21: =IF(I21="","",PERCENTRANK($I$2:$I$354,I21)) -> 0.936 | O21: =IF(K21="","",PERCENTRANK($K$2:$K$354,K21)) -> 0.835 | P21: =COUNT(M21:O21) -> 3 | Q21: 2022 populares #5 | W21: =COUNTA(Q21:V21) -> 1 | X21: =IF(P21=0,"",MIN(1,AVERAGE(M21:O21)+Critérios!$B$5*W21)) -> 0.862 | Y21: =IF(X21="","",IF(X21>=Critérios!$B$7,"A",IF(X21>=Critérios!$B$8,"B","C"))) -> A | Z21: =IF(X21="","",RANK(X21,$X$2:$X$354)) -> 21 | AA21: =IF(X21="","Sairia — sem métrica",IF(PERCENTRANK($X$2:$X$354,X21)<Critérios!$B$6,"Sairia — terço inferior","Fica")) -> Fica | AB21: a avaliar | AD21: candidato | AF21: S055, S200 | AG21: tt1745960 | AH21: =COUNT(G21,I21,K21)+COUNTA(Q21:V21) -> 4 | AI21: =IF(AH21>=3,"Sim","Não") -> Sim | AJ21: =IF(AND(Z21<>"",Z21<=Critérios!$B$9),"Sim","Não") -> Sim
A22: F0021 | B22: Homem-Aranha Longe de Casa | C22: Spider-Man: Far From Home | D22: 2019 | E22: Não | F22: Bilheteria (Ancine/Wikipédia) | G22: 6555353 | H22: 106552456 | I22: 1133927996 | J22: 4 | K22: 679969 | L22: 7.3 | M22: =IF(G22="","",PERCENTRANK($G$2:$G$354,G22)) -> 0.837 | N22: =IF(I22="","",PERCENTRANK($I$2:$I$354,I22)) -> 0.852 | O22: =IF(K22="","",PERCENTRANK($K$2:$K$354,K22)) -> 0.719 | P22: =COUNT(M22:O22) -> 3 | Q22: 2019 populares #8 | R22: #114 hoje | W22: =COUNTA(Q22:V22) -> 2 | X22: =IF(P22=0,"",MIN(1,AVERAGE(M22:O22)+Critérios!$B$5*W22)) -> 0.86266667 | Y22: =IF(X22="","",IF(X22>=Critérios!$B$7,"A",IF(X22>=Critérios!$B$8,"B","C"))) -> A | Z22: =IF(X22="","",RANK(X22,$X$2:$X$354)) -> 20 | AA22: =IF(X22="","Sairia — sem métrica",IF(PERCENTRANK($X$2:$X$354,X22)<Critérios!$B$6,"Sairia — terço inferior","Fica")) -> Fica | AB22: a avaliar | AD22: candidato | AF22: S052, S208 | AG22: tt6320628 | AH22: =COUNT(G22,I22,K22)+COUNTA(Q22:V22) -> 5 | AI22: =IF(AH22>=3,"Sim","Não") -> Sim | AJ22: =IF(AND(Z22<>"",Z22<=Critérios!$B$9),"Sim","Não") -> Sim
A23: F0022 | B23: Capitã Marvel | C23: Captain Marvel | D23: 2019 | E23: Não | F23: Bilheteria (Ancine/Wikipédia) | G23: 8993389 | H23: 146783970 | I23: 1131274794 | J23: 5 | K23: 675498 | L23: 6.7 | M23: =IF(G23="","",PERCENTRANK($G$2:$G$354,G23)) -> 0.938 | N23: =IF(I23="","",PERCENTRANK($I$2:$I$354,I23)) -> 0.847 | O23: =IF(K23="","",PERCENTRANK($K$2:$K$354,K23)) -> 0.71 | P23: =COUNT(M23:O23) -> 3 | Q23: 2019 populares #6 | W23: =COUNTA(Q23:V23) -> 1 | X23: =IF(P23=0,"",MIN(1,AVERAGE(M23:O23)+Critérios!$B$5*W23)) -> 0.86166667 | Y23: =IF(X23="","",IF(X23>=Critérios!$B$7,"A",IF(X23>=Critérios!$B$8,"B","C"))) -> A | Z23: =IF(X23="","",RANK(X23,$X$2:$X$354)) -> 22 | AA23: =IF(X23="","Sairia — sem métrica",IF(PERCENTRANK($X$2:$X$354,X23)<Critérios!$B$6,"Sairia — terço inferior","Fica")) -> Fica | AB23: a avaliar | AD23: candidato | AF23: S052, S192, S201, S208 | AG23: tt4154664 | AH23: =COUNT(G23,I23,K23)+COUNTA(Q23:V23) -> 4 | AI23: =IF(AH23>=3,"Sim","Não") -> Sim | AJ23: =IF(AND(Z23<>"",Z23<=Critérios!$B$9),"Sim","Não") -> Sim
A24: F0023 | B24: O Jogo da Imitação | C24: The Imitation Game | D24: 2014 | E24: Não | F24: Adicionado por: JustWatch Brasil | K24: 887022 | L24: 8 | M24: =IF(G24="","",PERCENTRANK($G$2:$G$354,G24)) | N24: =IF(I24="","",PERCENTRANK($I$2:$I$354,I24)) | O24: =IF(K24="","",PERCENTRANK($K$2:$K$354,K24)) -> 0.827 | P24: =COUNT(M24:O24) -> 1 | R24: #89 hoje | W24: =COUNTA(Q24:V24) -> 1 | X24: =IF(P24=0,"",MIN(1,AVERAGE(M24:O24)+Critérios!$B$5*W24)) -> 0.857 | Y24: =IF(X24="","",IF(X24>=Critérios!$B$7,"A",IF(X24>=Critérios!$B$8,"B","C"))) -> A | Z24: =IF(X24="","",RANK(X24,$X$2:$X$354)) -> 23 | AA24: =IF(X24="","Sairia — sem métrica",IF(PERCENTRANK($X$2:$X$354,X24)<Critérios!$B$6,"Sairia — terço inferior","Fica")) -> Fica | AB24: a avaliar | AC24: Resgatado manualmente (lista aprovada em 13/10/2026) | AD24: candidato | AG24: tt2084970 | AH24: =COUNT(G24,I24,K24)+COUNTA(Q24:V24) -> 2 | AI24: =IF(AH24>=3,"Sim","Não") -> Não | AJ24: =IF(AND(Z24<>"",Z24<=Critérios!$B$9),"Sim","Não") -> Sim
A25: F0024 | B25: Batman: O Cavaleiro das Trevas Ressurge | C25: The Dark Knight Rises | D25: 2012 | E25: Não | F25: Bilheteria (Ancine/Wikipédia) | G25: 5146519 | H25: 55062755 | I25: 1081041287 | J25: 3 | K25: 2032805 | L25: 8.4 | M25: =IF(G25="","",PERCENTRANK($G$2:$G$354,G25)) -> 0.742 | N25: =IF(I25="","",PERCENTRANK($I$2:$I$354,I25)) -> 0.826 | O25: =IF(K25="","",PERCENTRANK($K$2:$K$354,K25)) -> 0.986 | P25: =COUNT(M25:O25) -> 3 | W25: =COUNTA(Q25:V25) -> 0 | X25: =IF(P25=0,"",MIN(1,AVERAGE(M25:O25)+Critérios!$B$5*W25)) -> 0.85133333 | Y25: =IF(X25="","",IF(X25>=Critérios!$B$7,"A",IF(X25>=Critérios!$B$8,"B","C"))) -> A | Z25: =IF(X25="","",RANK(X25,$X$2:$X$354)) -> 24 | AA25: =IF(X25="","Sairia — sem métrica",IF(PERCENTRANK($X$2:$X$354,X25)<Critérios!$B$6,"Sairia — terço inferior","Fica")) -> Fica | AB25: a avaliar | AD25: candidato | AF25: S045, S205 | AG25: tt1345836 | AH25: =COUNT(G25,I25,K25)+COUNTA(Q25:V25) -> 3 | AI25: =IF(AH25>=3,"Sim","Não") -> Sim | AJ25: =IF(AND(Z25<>"",Z25<=Critérios!$B$9),"Sim","Não") -> Sim
A26: F0025 | B26: Jurassic World: O mundo dos dinossauros | C26: Jurassic World | D26: 2015 | E26: Não | F26: Bilheteria (Ancine/Wikipédia) | G26: 6356559 | H26: 90707161 | I26: 1671537444 | J26: 2 | K26: 739583 | L26: 6.9 | M26: =IF(G26="","",PERCENTRANK($G$2:$G$354,G26)) -> 0.824 | N26: =IF(I26="","",PERCENTRANK($I$2:$I$354,I26)) -> 0.958 | O26: =IF(K26="","",PERCENTRANK($K$2:$K$354,K26)) -> 0.75 | P26: =COUNT(M26:O26) -> 3 | W26: =COUNTA(Q26:V26) -> 0 | X26: =IF(P26=0,"",MIN(1,AVERAGE(M26:O26)+Critérios!$B$5*W26)) -> 0.844 | Y26: =IF(X26="","",IF(X26>=Critérios!$B$7,"A",IF(X26>=Critérios!$B$8,"B","C"))) -> A | Z26: =IF(X26="","",RANK(X26,$X$2:$X$354)) -> 25 | AA26: =IF(X26="","Sairia — sem métrica",IF(PERCENTRANK($X$2:$X$354,X26)<Critérios!$B$6,"Sairia — terço inferior","Fica")) -> Fica | AB26: ambíguo (provável) — conferir | AD26: candidato | AF26: S048, S202 | AG26: tt0369610 | AH26: =COUNT(G26,I26,K26)+COUNTA(Q26:V26) -> 3 | AI26: =IF(AH26>=3,"Sim","Não") -> Sim | AJ26: =IF(AND(Z26<>"",Z26<=Critérios!$B$9),"Sim","Não") -> Sim
A27: F0026 | B27: Deadpool & Wolverine | C27: Deadpool & Wolverine | D27: 2024 | E27: Não | F27: Bilheteria (Ancine/Wikipédia) | G27: 7365659 | H27: 155895852 | I27: 1338073645 | J27: 2 | K27: 597766 | L27: 7.5 | M27: =IF(G27="","",PERCENTRANK($G$2:$G$354,G27)) -> 0.866 | N27: =IF(I27="","",PERCENTRANK($I$2:$I$354,I27)) -> 0.903 | O27: =IF(K27="","",PERCENTRANK($K$2:$K$354,K27)) -> 0.67 | P27: =COUNT(M27:O27) -> 3 | Q27: 2024 populares #4 | W27: =COUNTA(Q27:V27) -> 1 | X27: =IF(P27=0,"",MIN(1,AVERAGE(M27:O27)+Critérios!$B$5*W27)) -> 0.843 | Y27: =IF(X27="","",IF(X27>=Critérios!$B$7,"A",IF(X27>=Critérios!$B$8,"B","C"))) -> A | Z27: =IF(X27="","",RANK(X27,$X$2:$X$354)) -> 26 | AA27: =IF(X27="","Sairia — sem métrica",IF(PERCENTRANK($X$2:$X$354,X27)<Critérios!$B$6,"Sairia — terço inferior","Fica")) -> Fica | AB27: a avaliar | AD27: candidato | AF27: S057, S209 | AG27: tt6263850 | AH27: =COUNT(G27,I27,K27)+COUNTA(Q27:V27) -> 4 | AI27: =IF(AH27>=3,"Sim","Não") -> Sim | AJ27: =IF(AND(Z27<>"",Z27<=Critérios!$B$9),"Sim","Não") -> Sim
A28: F0027 | B28: Homem-Aranha: De Volta ao Lar | C28: Spider-Man: Homecoming | D28: 2017 | E28: Não | F28: Bilheteria (Ancine/Wikipédia) | G28: 6686736 | H28: 102726271 | I28: 880166924 | J28: 6 | K28: 842372 | L28: 7.4 | M28: =IF(G28="","",PERCENTRANK($G$2:$G$354,G28)) -> 0.843 | N28: =IF(I28="","",PERCENTRANK($I$2:$I$354,I28)) -> 0.648 | O28: =IF(K28="","",PERCENTRANK($K$2:$K$354,K28)) -> 0.815 | P28: =COUNT(M28:O28) -> 3 | Q28: 2017 populares #9 | R28: #107 hoje | W28: =COUNTA(Q28:V28) -> 2 | X28: =IF(P28=0,"",MIN(1,AVERAGE(M28:O28)+Critérios!$B$5*W28)) -> 0.82866667 | Y28: =IF(X28="","",IF(X28>=Critérios!$B$7,"A",IF(X28>=Critérios!$B$8,"B","C"))) -> A | Z28: =IF(X28="","",RANK(X28,$X$2:$X$354)) -> 27 | AA28: =IF(X28="","Sairia — sem métrica",IF(PERCENTRANK($X$2:$X$354,X28)<Critérios!$B$6,"Sairia — terço inferior","Fica")) -> Fica | AB28: a avaliar | AD28: candidato | AF28: S050, S203 | AG28: tt2250912 | AH28: =COUNT(G28,I28,K28)+COUNTA(Q28:V28) -> 5 | AI28: =IF(AH28>=3,"Sim","Não") -> Sim | AJ28: =IF(AND(Z28<>"",Z28<=Critérios!$B$9),"Sim","Não") -> Sim
A29: F0028 | B29: Homem-Aranha: Um Novo Dia | C29: Spider-Man: Brand New Day | D29: 2026 | E29: Não | F29: Bilheteria (Ancine/Wikipédia) | G29: 18780000 | H29: 412100000 | I29: 2421842642 | J29: 1 | K29: 344361 | L29: 7.9 | M29: =IF(G29="","",PERCENTRANK($G$2:$G$354,G29)) -> 0.993 | N29: =IF(I29="","",PERCENTRANK($I$2:$I$354,I29)) -> 0.992 | O29: =IF(K29="","",PERCENTRANK($K$2:$K$354,K29)) -> 0.406 | P29: =COUNT(M29:O29) -> 3 | R29: #5 hoje | W29: =COUNTA(Q29:V29) -> 1 | X29: =IF(P29=0,"",MIN(1,AVERAGE(M29:O29)+Critérios!$B$5*W29)) -> 0.827 | Y29: =IF(X29="","",IF(X29>=Critérios!$B$7,"A",IF(X29>=Critérios!$B$8,"B","C"))) -> A | Z29: =IF(X29="","",RANK(X29,$X$2:$X$354)) -> 28 | AA29: =IF(X29="","Sairia — sem métrica",IF(PERCENTRANK($X$2:$X$354,X29)<Critérios!$B$6,"Sairia — terço inferior","Fica")) -> Fica | AB29: a avaliar | AC29: 2026: dados parciais | AD29: candidato | AF29: S059, S189 | AG29: tt22084616 | AH29: =COUNT(G29,I29,K29)+COUNTA(Q29:V29) -> 4 | AI29: =IF(AH29>=3,"Sim","Não") -> Sim | AJ29: =IF(AND(Z29<>"",Z29<=Critérios!$B$9),"Sim","Não") -> Sim
A30: F0029 | B30: Homem-Aranha | C30: Spider-Man | D30: 2002 | E30: Não | F30: Bilheteria (Ancine/Wikipédia) | G30: 8488182 | H30: 46026289 | I30: 821708551 | J30: 3 | K30: 1000733 | L30: 7.4 | M30: =IF(G30="","",PERCENTRANK($G$2:$G$354,G30)) -> 0.918 | N30: =IF(I30="","",PERCENTRANK($I$2:$I$354,I30)) -> 0.568 | O30: =IF(K30="","",PERCENTRANK($K$2:$K$354,K30)) -> 0.898 | P30: =COUNT(M30:O30) -> 3 | U30: UCLA Center for Scholars & Storytellers 2025-10 (10-24) #4 | W30: =COUNTA(Q30:V30) -> 1 | X30: =IF(P30=0,"",MIN(1,AVERAGE(M30:O30)+Critérios!$B$5*W30)) -> 0.82466667 | Y30: =IF(X30="","",IF(X30>=Critérios!$B$7,"A",IF(X30>=Critérios!$B$8,"B","C"))) -> A | Z30: =IF(X30="","",RANK(X30,$X$2:$X$354)) -> 29 | AA30: =IF(X30="","Sairia — sem métrica",IF(PERCENTRANK($X$2:$X$354,X30)<Critérios!$B$6,"Sairia — terço inferior","Fica")) -> Fica | AB30: a avaliar | AD30: candidato | AF30: S035, S180 | AG30: tt0145487 | AH30: =COUNT(G30,I30,K30)+COUNTA(Q30:V30) -> 4 | AI30: =IF(AH30>=3,"Sim","Não") -> Sim | AJ30: =IF(AND(Z30<>"",Z30<=Critérios!$B$9),"Sim","Não") -> Sim
A31: F0030 | B31: Batman vs Superman: a Origem da Justiça | C31: Batman v Superman: Dawn of Justice | D31: 2016 | E31: Não | F31: Bilheteria (Ancine/Wikipédia) | G31: 8565462 | H31: 132443918 | I31: 874360194 | J31: 7 | K31: 800609 | L31: 6.4 | M31: =IF(G31="","",PERCENTRANK($G$2:$G$354,G31)) -> 0.925 | N31: =IF(I31="","",PERCENTRANK($I$2:$I$354,I31)) -> 0.631 | O31: =IF(K31="","",PERCENTRANK($K$2:$K$354,K31)) -> 0.801 | P31: =COUNT(M31:O31) -> 3 | Q31: 2016 populares #4 | W31: =COUNTA(Q31:V31) -> 1 | X31: =IF(P31=0,"",MIN(1,AVERAGE(M31:O31)+Critérios!$B$5*W31)) -> 0.81566667 | Y31: =IF(X31="","",IF(X31>=Critérios!$B$7,"A",IF(X31>=Critérios!$B$8,"B","C"))) -> A | Z31: =IF(X31="","",RANK(X31,$X$2:$X$354)) -> 30 | AA31: =IF(X31="","Sairia — sem métrica",IF(PERCENTRANK($X$2:$X$354,X31)<Critérios!$B$6,"Sairia — terço inferior","Fica")) -> Fica | AB31: a avaliar | AD31: candidato | AF31: S049, S191, S201, S207 | AG31: tt2975590 | AH31: =COUNT(G31,I31,K31)+COUNTA(Q31:V31) -> 4 | AI31: =IF(AH31>=3,"Sim","Não") -> Sim | AJ31: =IF(AND(Z31<>"",Z31<=Critérios!$B$9),"Sim","Não") -> Sim
A32: F0031 | B32: O Senhor dos Anéis: O Retorno do Rei | C32: The Lord of the Rings: The Return of the King | D32: 2003 | E32: Não | F32: Bilheteria (Ancine/Wikipédia) | G32: 4268649 | H32: 28906614 | I32: 1118887224 | J32: 1 | K32: 2200389 | L32: 9 | M32: =IF(G32="","",PERCENTRANK($G$2:$G$354,G32)) -> 0.608 | N32: =IF(I32="","",PERCENTRANK($I$2:$I$354,I32)) -> 0.839 | O32: =IF(K32="","",PERCENTRANK($K$2:$K$354,K32)) -> 0.989 | P32: =COUNT(M32:O32) -> 3 | W32: =COUNTA(Q32:V32) -> 0 | X32: =IF(P32=0,"",MIN(1,AVERAGE(M32:O32)+Critérios!$B$5*W32)) -> 0.812 | Y32: =IF(X32="","",IF(X32>=Critérios!$B$7,"A",IF(X32>=Critérios!$B$8,"B","C"))) -> A | Z32: =IF(X32="","",RANK(X32,$X$2:$X$354)) -> 31 | AA32: =IF(X32="","Sairia — sem métrica",IF(PERCENTRANK($X$2:$X$354,X32)<Critérios!$B$6,"Sairia — terço inferior","Fica")) -> Fica | AB32: ambíguo (provável) — conferir | AD32: candidato | AF32: S036, S181 | AG32: tt0167260 | AH32: =COUNT(G32,I32,K32)+COUNTA(Q32:V32) -> 3 | AI32: =IF(AH32>=3,"Sim","Não") -> Sim | AJ32: =IF(AND(Z32<>"",Z32<=Critérios!$B$9),"Sim","Não") -> Sim
A33: F0032 | B33: Não Olhe para Cima | C33: Don't Look Up | D33: 2021 | E33: Não | F33: Adicionado por: Nielsen | K33: 683308 | L33: 7.1 | M33: =IF(G33="","",PERCENTRANK($G$2:$G$354,G33)) | N33: =IF(I33="","",PERCENTRANK($I$2:$I$354,I33)) | O33: =IF(K33="","",PERCENTRANK($K$2:$K$354,K33)) -> 0.722 | P33: =COUNT(M33:O33) -> 1 | Q33: 2021 populares #8 | S33: 2022 #7 | T33: fim de semana 7–9 jan 2022 #2 (United States); 18–20 fev 2022 #10 (United States) | W33: =COUNTA(Q33:V33) -> 3 | X33: =IF(P33=0,"",MIN(1,AVERAGE(M33:O33)+Critérios!$B$5*W33)) -> 0.812 | Y33: =IF(X33="","",IF(X33>=Critérios!$B$7,"A",IF(X33>=Critérios!$B$8,"B","C"))) -> A | Z33: =IF(X33="","",RANK(X33,$X$2:$X$354)) -> 31 | AA33: =IF(X33="","Sairia — sem métrica",IF(PERCENTRANK($X$2:$X$354,X33)<Critérios!$B$6,"Sairia — terço inferior","Fica")) -> Fica | AB33: a avaliar | AD33: candidato | AG33: tt11286314 | AH33: =COUNT(G33,I33,K33)+COUNTA(Q33:V33) -> 4 | AI33: =IF(AH33>=3,"Sim","Não") -> Sim | AJ33: =IF(AND(Z33<>"",Z33<=Critérios!$B$9),"Sim","Não") -> Sim
A34: F0033 | B34: Doutor Estranho no Multiverso da Loucura | C34: Doctor Strange in the Multiverse of Madness | D34: 2022 | E34: Não | F34: Bilheteria (Ancine/Wikipédia) | G34: 8293496 | H34: 167507986 | I34: 960775804 | J34: 4 | K34: 563046 | L34: 6.8 | M34: =IF(G34="","",PERCENTRANK($G$2:$G$354,G34)) -> 0.908 | N34: =IF(I34="","",PERCENTRANK($I$2:$I$354,I34)) -> 0.699 | O34: =IF(K34="","",PERCENTRANK($K$2:$K$354,K34)) -> 0.642 | P34: =COUNT(M34:O34) -> 3 | Q34: 2022 populares #4 | T34: 15–17 jul 2022 #3 (United States); 22–24 jul 2022 #2 (United States) | W34: =COUNTA(Q34:V34) -> 2 | X34: =IF(P34=0,"",MIN(1,AVERAGE(M34:O34)+Critérios!$B$5*W34)) -> 0.80966667 | Y34: =IF(X34="","",IF(X34>=Critérios!$B$7,"A",IF(X34>=Critérios!$B$8,"B","C"))) -> A | Z34: =IF(X34="","",RANK(X34,$X$2:$X$354)) -> 33 | AA34: =IF(X34="","Sairia — sem métrica",IF(PERCENTRANK($X$2:$X$354,X34)<Critérios!$B$6,"Sairia — terço inferior","Fica")) -> Fica | AB34: a avaliar | AD34: candidato | AF34: S055, S200 | AG34: tt9419884 | AH34: =COUNT(G34,I34,K34)+COUNTA(Q34:V34) -> 5 | AI34: =IF(AH34>=3,"Sim","Não") -> Sim | AJ34: =IF(AND(Z34<>"",Z34<=Critérios!$B$9),"Sim","Não") -> Sim
A35: F0034 | B35: Velozes e Furiosos 7 | C35: Furious 7 | D35: 2015 | E35: Não | F35: Bilheteria (Ancine/Wikipédia) | G35: 9857968 | H35: 142466037 | I35: 1515341399 | J35: 3 | K35: 445858 | L35: 7.1 | M35: =IF(G35="","",PERCENTRANK($G$2:$G$354,G35)) -> 0.964 | N35: =IF(I35="","",PERCENTRANK($I$2:$I$354,I35)) -> 0.941 | O35: =IF(K35="","",PERCENTRANK($K$2:$K$354,K35)) -> 0.514 | P35: =COUNT(M35:O35) -> 3 | W35: =COUNTA(Q35:V35) -> 0 | X35: =IF(P35=0,"",MIN(1,AVERAGE(M35:O35)+Critérios!$B$5*W35)) -> 0.80633333 | Y35: =IF(X35="","",IF(X35>=Critérios!$B$7,"A",IF(X35>=Critérios!$B$8,"B","C"))) -> A | Z35: =IF(X35="","",RANK(X35,$X$2:$X$354)) -> 34 | AA35: =IF(X35="","Sairia — sem métrica",IF(PERCENTRANK($X$2:$X$354,X35)<Critérios!$B$6,"Sairia — terço inferior","Fica")) -> Fica | AB35: ambíguo (provável) — conferir | AD35: candidato | AF35: S048, S191, S192, S201, S202 | AG35: tt2820852 | AH35: =COUNT(G35,I35,K35)+COUNTA(Q35:V35) -> 3 | AI35: =IF(AH35>=3,"Sim","Não") -> Sim | AJ35: =IF(AND(Z35<>"",Z35<=Critérios!$B$9),"Sim","Não") -> Sim
A36: F0035 | B36: A Odisseia | C36: The Odyssey | D36: 2026 | E36: Não | F36: Bilheteria (Ancine/Wikipédia) | G36: 5330290 | H36: 131030000 | I36: 1657467504 | J36: 2 | K36: 526880 | L36: 8.4 | M36: =IF(G36="","",PERCENTRANK($G$2:$G$354,G36)) -> 0.761 | N36: =IF(I36="","",PERCENTRANK($I$2:$I$354,I36)) -> 0.949 | O36: =IF(K36="","",PERCENTRANK($K$2:$K$354,K36)) -> 0.614 | P36: =COUNT(M36:O36) -> 3 | R36: #16 hoje | W36: =COUNTA(Q36:V36) -> 1 | X36: =IF(P36=0,"",MIN(1,AVERAGE(M36:O36)+Critérios!$B$5*W36)) -> 0.80466667 | Y36: =IF(X36="","",IF(X36>=Critérios!$B$7,"A",IF(X36>=Critérios!$B$8,"B","C"))) -> A | Z36: =IF(X36="","",RANK(X36,$X$2:$X$354)) -> 35 | AA36: =IF(X36="","Sairia — sem métrica",IF(PERCENTRANK($X$2:$X$354,X36)<Critérios!$B$6,"Sairia — terço inferior","Fica")) -> Fica | AB36: a avaliar | AC36: 2026: dados parciais | AD36: candidato | AF36: S059, S189 | AG36: tt33764258 | AH36: =COUNT(G36,I36,K36)+COUNTA(Q36:V36) -> 4 | AI36: =IF(AH36>=3,"Sim","Não") -> Sim | AJ36: =IF(AND(Z36<>"",Z36<=Critérios!$B$9),"Sim","Não") -> Sim
A37: F0036 | B37: Doutor Estranho | C37: Doctor Strange | D37: 2016 | E37: Não | F37: Bilheteria (Ancine/Wikipédia) | G37: 4797512 | H37: 74731453 | K37: 900827 | L37: 7.5 | M37: =IF(G37="","",PERCENTRANK($G$2:$G$354,G37)) -> 0.716 | N37: =IF(I37="","",PERCENTRANK($I$2:$I$354,I37)) | O37: =IF(K37="","",PERCENTRANK($K$2:$K$354,K37)) -> 0.832 | P37: =COUNT(M37:O37) -> 2 | Q37: 2016 populares #15 | W37: =COUNTA(Q37:V37) -> 1 | X37: =IF(P37=0,"",MIN(1,AVERAGE(M37:O37)+Critérios!$B$5*W37)) -> 0.804 | Y37: =IF(X37="","",IF(X37>=Critérios!$B$7,"A",IF(X37>=Critérios!$B$8,"B","C"))) -> A | Z37: =IF(X37="","",RANK(X37,$X$2:$X$354)) -> 36 | AA37: =IF(X37="","Sairia — sem métrica",IF(PERCENTRANK($X$2:$X$354,X37)<Critérios!$B$6,"Sairia — terço inferior","Fica")) -> Fica | AB37: a avaliar | AD37: candidato | AF37: S207 | AG37: tt1211837 | AH37: =COUNT(G37,I37,K37)+COUNTA(Q37:V37) -> 3 | AI37: =IF(AH37>=3,"Sim","Não") -> Sim | AJ37: =IF(AND(Z37<>"",Z37<=Critérios!$B$9),"Sim","Não") -> Sim
A38: F0037 | B38: Batman – O Cavaleiro das Trevas | C38: The Dark Knight | D38: 2008 | E38: Não | F38: Bilheteria (Ancine/Wikipédia) | G38: 4026563 | H38: 32773928 | I38: 997000000 | J38: 1 | K38: 3238631 | L38: 9.1 | M38: =IF(G38="","",PERCENTRANK($G$2:$G$354,G38)) -> 0.575 | N38: =IF(I38="","",PERCENTRANK($I$2:$I$354,I38)) -> 0.746 | O38: =IF(K38="","",PERCENTRANK($K$2:$K$354,K38)) -> 1 | P38: =COUNT(M38:O38) -> 3 | Q38: populares de todos os tempos #7; populares de todos os tempos #6 | W38: =COUNTA(Q38:V38) -> 1 | X38: =IF(P38=0,"",MIN(1,AVERAGE(M38:O38)+Critérios!$B$5*W38)) -> 0.80366667 | Y38: =IF(X38="","",IF(X38>=Critérios!$B$7,"A",IF(X38>=Critérios!$B$8,"B","C"))) -> A | Z38: =IF(X38="","",RANK(X38,$X$2:$X$354)) -> 37 | AA38: =IF(X38="","Sairia — sem métrica",IF(PERCENTRANK($X$2:$X$354,X38)<Critérios!$B$6,"Sairia — terço inferior","Fica")) -> Fica | AB38: a avaliar | AD38: candidato | AF38: S041, S186 | AG38: tt0468569 | AH38: =COUNT(G38,I38,K38)+COUNTA(Q38:V38) -> 4 | AI38: =IF(AH38>=3,"Sim","Não") -> Sim | AJ38: =IF(AND(Z38<>"",Z38<=Critérios!$B$9),"Sim","Não") -> Sim
A39: F0038 | B39: Os Incríveis 2 | C39: Incredibles 2 | D39: 2018 | E39: Não | F39: Bilheteria (Ancine/Wikipédia) | G39: 9809521 | H39: 145012895 | I39: 1242805359 | J39: 4 | K39: 378977 | L39: 7.5 | M39: =IF(G39="","",PERCENTRANK($G$2:$G$354,G39)) -> 0.961 | N39: =IF(I39="","",PERCENTRANK($I$2:$I$354,I39)) -> 0.881 | O39: =IF(K39="","",PERCENTRANK($K$2:$K$354,K39)) -> 0.446 | P39: =COUNT(M39:O39) -> 3 | Q39: 2018 populares #6 | W39: =COUNTA(Q39:V39) -> 1 | X39: =IF(P39=0,"",MIN(1,AVERAGE(M39:O39)+Critérios!$B$5*W39)) -> 0.79266667 | Y39: =IF(X39="","",IF(X39>=Critérios!$B$7,"A",IF(X39>=Critérios!$B$8,"B","C"))) -> A | Z39: =IF(X39="","",RANK(X39,$X$2:$X$354)) -> 38 | AA39: =IF(X39="","Sairia — sem métrica",IF(PERCENTRANK($X$2:$X$354,X39)<Critérios!$B$6,"Sairia — terço inferior","Fica")) -> Fica | AB39: ambíguo (provável) — conferir | AD39: candidato | AF39: S051, S191, S192, S201 | AG39: tt3606756 | AH39: =COUNT(G39,I39,K39)+COUNTA(Q39:V39) -> 4 | AI39: =IF(AH39>=3,"Sim","Não") -> Sim | AJ39: =IF(AND(Z39<>"",Z39<=Critérios!$B$9),"Sim","Não") -> Sim
A40: F0039 | B40: Deadpool | C40: Deadpool | D40: 2016 | E40: Não | F40: Bilheteria (Ancine/Wikipédia) | G40: 6044324 | H40: 81932430 | I40: 782612155 | J40: 9 | K40: 1275146 | L40: 8 | M40: =IF(G40="","",PERCENTRANK($G$2:$G$354,G40)) -> 0.807 | N40: =IF(I40="","",PERCENTRANK($I$2:$I$354,I40)) -> 0.525 | O40: =IF(K40="","",PERCENTRANK($K$2:$K$354,K40)) -> 0.952 | P40: =COUNT(M40:O40) -> 3 | Q40: 2016 populares #1 | W40: =COUNTA(Q40:V40) -> 1 | X40: =IF(P40=0,"",MIN(1,AVERAGE(M40:O40)+Critérios!$B$5*W40)) -> 0.79133333 | Y40: =IF(X40="","",IF(X40>=Critérios!$B$7,"A",IF(X40>=Critérios!$B$8,"B","C"))) -> A | Z40: =IF(X40="","",RANK(X40,$X$2:$X$354)) -> 39 | AA40: =IF(X40="","Sairia — sem métrica",IF(PERCENTRANK($X$2:$X$354,X40)<Critérios!$B$6,"Sairia — terço inferior","Fica")) -> Fica | AB40: a avaliar | AD40: candidato | AF40: S049, S207 | AG40: tt1431045 | AH40: =COUNT(G40,I40,K40)+COUNTA(Q40:V40) -> 4 | AI40: =IF(AH40>=3,"Sim","Não") -> Sim | AJ40: =IF(AND(Z40<>"",Z40<=Critérios!$B$9),"Sim","Não") -> Sim
...

Sheet Séries
A1: ID | B1: Título no Brasil | C1: Título original | D1: Ano de estreia | E1: Origem / canal | F1: Origem na base | G1: Votos no IMDb | H1: Nota IMDb | I1: Netflix: views 91 dias (maior temporada) | J1: Netflix: posição no Top 10 histórico | K1: Audiência média por temporada (maior) | L1: Tipo da audiência média | M1: Nielsen: melhor posição | N1: Nielsen: tamanho da lista | O1: Nielsen: aparições | P1: Percentil votos IMDb | Q1: Pontuação Netflix | R1: Pontuação Nielsen | S1: Pontuação audiência média | T1: Audiência oficial (melhor) | U1: Nº de métricas | V1: Selo Geração Z | W1: Selo Parrot BR | X1: Selo Whip Media | Y1: Selo JustWatch BR | Z1: Nº de selos | AA1: Índice | AB1: Faixa | AC1: Posição | AD1: Terço inferior da base final (informativo) | AE1: Protagonista (preliminar) | AF1: Alertas de conteúdo | AG1: Conferir | AH1: Status | AI1: Notas editoriais | AJ1: Fontes | AK1: IMDb ID | AL1: Nº de bases em que aparece | AM1: Presente em ≥3 bases | AN1: Seleção Sucessos
A2: S0001 | B2: Stranger Things | C2: Stranger Things | D2: 2016 | E2: Netflix | F2: Audiência oficial (coleta) | G2: 1746147 | H2: 8.6 | I2: 140700000 | J2: 3 | M2: 1 | N2: 30 | O2: 2022 #1; 2025 #3; 2025 #1 | P2: =IF(G2="","",PERCENTRANK($G$2:$G$85,G2)) -> 0.976 | Q2: =IF(J2="","",1-(J2-1)/20) -> 0.9 | R2: =IF(M2="","",1-(M2-1)/(2*N2)) -> 1 | S2: =IF(K2="","",0.5+0.5*PERCENTRANK($K$2:$K$85,K2)) | T2: =IF(COUNT(Q2:S2)=0,"",MAX(Q2:S2)) -> 1 | U2: =COUNT(P2,T2) -> 2 | V2: YPulse 2024-02 (13-17) #1; YPulse 2024-02 (18-24) #3; YPulse Media Consumption Monitor 2022-10 (Gen Z (faixa não explicitada; amostra 13-39)) #1; YPulse 2023-11 (13-17); YPulse 2023-11 (18-24); YPulse 2024-09 (Gen Z teens and young adults (faixa não explicitada)); YPulse 2025-02 (Gen Z (faixa não explicitada)); YPulse 2016-09 (teens (13-17 presumido; amostra 13-33)); UCLA Center for Scholars & Storytellers 2025-10 (10-24) #1; UCLA Teens & Screens 2023 2023-10 (10-24); Morning Consult 2022-12 (13-25) #6 | W2: 2020 (ano) #1; fev 2020 #2 | X2: semana encerrada 19 jun 2022 #3 (United States); semana encerrada 17 jul 2022 #1 (United States); semana encerrada 24 jul 2022 #3 (United States) | Y2: #144 hoje | Z2: =COUNTA(V2:Y2) -> 4 | AA2: =IF(U2=0,"",MIN(1,AVERAGE(P2,T2)+Critérios!$B$5*Z2)) -> 1 | AB2: =IF(AA2="","",IF(AA2>=Critérios!$B$7,"A",IF(AA2>=Critérios!$B$8,"B","C"))) -> A | AC2: =IF(AA2="","",RANK(AA2,$AA$2:$AA$85)) -> 1 | AD2: =IF(AA2="","Sairia — sem métrica",IF(PERCENTRANK($AA$2:$AA$85,AA2)<Critérios!$B$6,"Sairia — terço inferior","Fica")) -> Fica | AE2: coral/antologia | AH2: candidato | AJ2: S030 | AK2: tt4574334 | AL2: =COUNT(G2)+IF(OR(I2<>"",K2<>""),1,0)+IF(M2<>"",1,0)+COUNTA(V2:Y2) -> 7 | AM2: =IF(AL2>=3,"Sim","Não") -> Sim | AN2: =IF(AND(AC2<>"",AC2<=Critérios!$B$9),"Sim","Não") -> Sim
A3: S0002 | B3: The Big Bang Theory | C3: The Big Bang Theory | D3: 2007 | E3: CBS | F3: Audiência oficial (coleta) | G3: 948462 | H3: 8.1 | K3: 20360000 | M3: 1 | N3: 40 | O3: 2009-10 #14; 2010-11 #14; 2011-12 #8; 2012-13 #3; 2013-14 #3; 2014-15 #2; 2015-16 #3; 2016-17 #1; 2017-18 #1; 2018-19 #2; 2023 #6; 2024 #7; 2025 #8 | P3: =IF(G3="","",PERCENTRANK($G$2:$G$85,G3)) -> 0.904 | Q3: =IF(J3="","",1-(J3-1)/20) | R3: =IF(M3="","",1-(M3-1)/(2*N3)) -> 1 | S3: =IF(K3="","",0.5+0.5*PERCENTRANK($K$2:$K$85,K3)) -> 0.9375 | T3: =IF(COUNT(Q3:S3)=0,"",MAX(Q3:S3)) -> 1 | U3: =COUNT(P3,T3) -> 2 | W3: Q1 2022 #21; Q2 2023 #25 | Y3: #92 hoje | Z3: =COUNTA(V3:Y3) -> 2 | AA3: =IF(U3=0,"",MIN(1,AVERAGE(P3,T3)+Critérios!$B$5*Z3)) -> 1 | AB3: =IF(AA3="","",IF(AA3>=Critérios!$B$7,"A",IF(AA3>=Critérios!$B$8,"B","C"))) -> A | AC3: =IF(AA3="","",RANK(AA3,$AA$2:$AA$85)) -> 1 | AD3: =IF(AA3="","Sairia — sem métrica",IF(PERCENTRANK($AA$2:$AA$85,AA3)<Critérios!$B$6,"Sairia — terço inferior","Fica")) -> Fica | AE3: coral/antologia | AH3: candidato | AJ3: S021 | AK3: tt0898266 | AL3: =COUNT(G3)+IF(OR(I3<>"",K3<>""),1,0)+IF(M3<>"",1,0)+COUNTA(V3:Y3) -> 5 | AM3: =IF(AL3>=3,"Sim","Não") -> Sim | AN3: =IF(AND(AC3<>"",AC3<=Critérios!$B$9),"Sim","Não") -> Sim
A4: S0003 | B4: The Boys | C4: The Boys | D4: 2019 | E4: Prime Video | F4: Audiência oficial (coleta) | G4: 1030960 | H4: 8.5 | M4: 3 | N4: 30 | O4: 2022 #11; 2024 #3 | P4: =IF(G4="","",PERCENTRANK($G$2:$G$85,G4)) -> 0.928 | Q4: =IF(J4="","",1-(J4-1)/20) | R4: =IF(M4="","",1-(M4-1)/(2*N4)) -> 0.96666667 | S4: =IF(K4="","",0.5+0.5*PERCENTRANK($K$2:$K$85,K4)) | T4: =IF(COUNT(Q4:S4)=0,"",MAX(Q4:S4)) -> 0.96666667 | U4: =COUNT(P4,T4) -> 2 | V4: YPulse 2024-02 (18-24) #8 | W4: 2020 (ano); ago 2020; fev 2021 | X4: semana encerrada 19 jun 2022 #1 (United States); semana encerrada 17 jul 2022 #3 (United States); semana encerrada 24 jul 2022 #6 (United States); 2020 (ano) #1 (United States) | Z4: =COUNTA(V4:Y4) -> 3 | AA4: =IF(U4=0,"",MIN(1,AVERAGE(P4,T4)+Critérios!$B$5*Z4)) -> 1 | AB4: =IF(AA4="","",IF(AA4>=Critérios!$B$7,"A",IF(AA4>=Critérios!$B$8,"B","C"))) -> A | AC4: =IF(AA4="","",RANK(AA4,$AA$2:$AA$85)) -> 1 | AD4: =IF(AA4="","Sairia — sem métrica",IF(PERCENTRANK($AA$2:$AA$85,AA4)<Critérios!$B$6,"Sairia — terço inferior","Fica")) -> Fica | AE4: coral/antologia | AF4: Classificação alta — pistas suaves | AH4: candidato | AJ4: S024 | AK4: tt1190634 | AL4: =COUNT(G4)+IF(OR(I4<>"",K4<>""),1,0)+IF(M4<>"",1,0)+COUNTA(V4:Y4) -> 5 | AM4: =IF(AL4>=3,"Sim","Não") -> Sim | AN4: =IF(AND(AC4<>"",AC4<=Critérios!$B$9),"Sim","Não") -> Sim
A5: S0004 | B5: The Office | C5: The Office | D5: 2005 | E5: NBC | F5: Audiência oficial (coleta) | G5: 854849 | H5: 9 | K5: 9000000 | M5: 1 | N5: 30 | O5: 2020 #1 | P5: =IF(G5="","",PERCENTRANK($G$2:$G$85,G5)) -> 0.88 | Q5: =IF(J5="","",1-(J5-1)/20) | R5: =IF(M5="","",1-(M5-1)/(2*N5)) -> 1 | S5: =IF(K5="","",0.5+0.5*PERCENTRANK($K$2:$K$85,K5)) -> 0.719 | T5: =IF(COUNT(Q5:S5)=0,"",MAX(Q5:S5)) -> 1 | U5: =COUNT(P5,T5) -> 2 | V5: YPulse 2020-05 (Gen Z (subgrupos 13-18 e 19-25 só em imagem)) #3 | Y5: #74 hoje | Z5: =COUNTA(V5:Y5) -> 2 | AA5: =IF(U5=0,"",MIN(1,AVERAGE(P5,T5)+Critérios!$B$5*Z5)) -> 1 | AB5: =IF(AA5="","",IF(AA5>=Critérios!$B$7,"A",IF(AA5>=Critérios!$B$8,"B","C"))) -> A | AC5: =IF(AA5="","",RANK(AA5,$AA$2:$AA$85)) -> 1 | AD5: =IF(AA5="","Sairia — sem métrica",IF(PERCENTRANK($AA$2:$AA$85,AA5)<Critérios!$B$6,"Sairia — terço inferior","Fica")) -> Fica | AE5: coral/antologia | AH5: candidato | AJ5: S022 | AK5: tt0386676 | AL5: =COUNT(G5)+IF(OR(I5<>"",K5<>""),1,0)+IF(M5<>"",1,0)+COUNTA(V5:Y5) -> 5 | AM5: =IF(AL5>=3,"Sim","Não") -> Sim | AN5: =IF(AND(AC5<>"",AC5<=Critérios!$B$9),"Sim","Não") -> Sim
A6: S0005 | B6: Round 6 | C6: Squid Game | D6: 2021 | E6: Netflix | F6: Audiência oficial (coleta) | G6: 779793 | H6: 7.9 | I6: 265200000 | J6: 1 | M6: 2 | N6: 30 | O6: 2021 #2; 2025 #2 | P6: =IF(G6="","",PERCENTRANK($G$2:$G$85,G6)) -> 0.843 | Q6: =IF(J6="","",1-(J6-1)/20) -> 1 | R6: =IF(M6="","",1-(M6-1)/(2*N6)) -> 0.98333333 | S6: =IF(K6="","",0.5+0.5*PERCENTRANK($K$2:$K$85,K6)) | T6: =IF(COUNT(Q6:S6)=0,"",MAX(Q6:S6)) -> 1 | U6: =COUNT(P6,T6) -> 2 | V6: YPulse 2025-02 (Gen Z (faixa não explicitada)); YPulse 2025-09 (Gen Z (faixa não explicitada)); UCLA Teens & Screens 2025 (top 25) 2025-10 (10-24) | X6: semana 18–24 out 2021 #2 (France); semana 25–31 out 2021 #3 (Italy); semana 1–7 nov 2021 #4 (Spain); semana 8–14 nov 2021 #5 (Germany); semana 15–21 nov 2021 #8 (France) | Z6: =COUNTA(V6:Y6) -> 2 | AA6: =IF(U6=0,"",MIN(1,AVERAGE(P6,T6)+Critérios!$B$5*Z6)) -> 0.9815 | AB6: =IF(AA6="","",IF(AA6>=Critérios!$B$7,"A",IF(AA6>=Critérios!$B$8,"B","C"))) -> A | AC6: =IF(AA6="","",RANK(AA6,$AA$2:$AA$85)) -> 5 | AD6: =IF(AA6="","Sairia — sem métrica",IF(PERCENTRANK($AA$2:$AA$85,AA6)<Critérios!$B$6,"Sairia — terço inferior","Fica")) -> Fica | AE6: claro | AH6: candidato | AJ6: S031 | AK6: tt10919420 | AL6: =COUNT(G6)+IF(OR(I6<>"",K6<>""),1,0)+IF(M6<>"",1,0)+COUNTA(V6:Y6) -> 5 | AM6: =IF(AL6>=3,"Sim","Não") -> Sim | AN6: =IF(AND(AC6<>"",AC6<=Critérios!$B$9),"Sim","Não") -> Sim
A7: S0006 | B7: The Walking Dead | C7: The Walking Dead | D7: 2010 | E7: AMC | F7: Audiência oficial (coleta) | G7: 1218228 | H7: 8.1 | K7: 14380000 | P7: =IF(G7="","",PERCENTRANK($G$2:$G$85,G7)) -> 0.964 | Q7: =IF(J7="","",1-(J7-1)/20) | R7: =IF(M7="","",1-(M7-1)/(2*N7)) | S7: =IF(K7="","",0.5+0.5*PERCENTRANK($K$2:$K$85,K7)) -> 0.8125 | T7: =IF(COUNT(Q7:S7)=0,"",MAX(Q7:S7)) -> 0.8125 | U7: =COUNT(P7,T7) -> 2 | V7: YPulse Media Consumption Monitor 2022-10 (Gen Z (faixa não explicitada; amostra 13-39)) #5; YPulse 2017-10 (Gen Z (faixa não explicitada; amostra 13-35)); YPulse 2016-09 (teens (13-17 presumido; amostra 13-33)) #1 | W7: 09 fev–09 mar 2023 #4 | Y7: #106 hoje | Z7: =COUNTA(V7:Y7) -> 3 | AA7: =IF(U7=0,"",MIN(1,AVERAGE(P7,T7)+Critérios!$B$5*Z7)) -> 0.97825 | AB7: =IF(AA7="","",IF(AA7>=Critérios!$B$7,"A",IF(AA7>=Critérios!$B$8,"B","C"))) -> A | AC7: =IF(AA7="","",RANK(AA7,$AA$2:$AA$85)) -> 6 | AD7: =IF(AA7="","Sairia — sem métrica",IF(PERCENTRANK($AA$2:$AA$85,AA7)<Critérios!$B$6,"Sairia — terço inferior","Fica")) -> Fica | AE7: coral/antologia | AF7: Classificação alta — pistas suaves | AH7: candidato | AJ7: S028 | AK7: tt1520211 | AL7: =COUNT(G7)+IF(OR(I7<>"",K7<>""),1,0)+IF(M7<>"",1,0)+COUNTA(V7:Y7) -> 5 | AM7: =IF(AL7>=3,"Sim","Não") -> Sim | AN7: =IF(AND(AC7<>"",AC7<=Critérios!$B$9),"Sim","Não") -> Sim
A8: S0007 | B8: Game of Thrones | C8: Game of Thrones | D8: 2011 | E8: HBO | F8: Audiência oficial (coleta) | G8: 2673165 | H8: 9.2 | K8: 11990000 | P8: =IF(G8="","",PERCENTRANK($G$2:$G$85,G8)) -> 0.988 | Q8: =IF(J8="","",1-(J8-1)/20) | R8: =IF(M8="","",1-(M8-1)/(2*N8)) | S8: =IF(K8="","",0.5+0.5*PERCENTRANK($K$2:$K$85,K8)) -> 0.7815 | T8: =IF(COUNT(Q8:S8)=0,"",MAX(Q8:S8)) -> 0.7815 | U8: =COUNT(P8,T8) -> 2 | V8: UCLA Teens & Screens 2025 (top 25) 2025-10 (10-24) | W8: 09 fev–09 mar 2023 #5 | Z8: =COUNTA(V8:Y8) -> 2 | AA8: =IF(U8=0,"",MIN(1,AVERAGE(P8,T8)+Critérios!$B$5*Z8)) -> 0.94475 | AB8: =IF(AA8="","",IF(AA8>=Critérios!$B$7,"A",IF(AA8>=Critérios!$B$8,"B","C"))) -> A | AC8: =IF(AA8="","",RANK(AA8,$AA$2:$AA$85)) -> 7 | AD8: =IF(AA8="","Sairia — sem métrica",IF(PERCENTRANK($AA$2:$AA$85,AA8)<Critérios!$B$6,"Sairia — terço inferior","Fica")) -> Fica | AE8: coral/antologia | AF8: Classificação alta — pistas suaves | AH8: candidato | AJ8: S006, S025 | AK8: tt0944947 | AL8: =COUNT(G8)+IF(OR(I8<>"",K8<>""),1,0)+IF(M8<>"",1,0)+COUNTA(V8:Y8) -> 4 | AM8: =IF(AL8>=3,"Sim","Não") -> Sim | AN8: =IF(AND(AC8<>"",AC8<=Critérios!$B$9),"Sim","Não") -> Sim
A9: S0008 | B9: Chernobyl | C9: Chernobyl | D9: 2019 | E9: HBO | F9: Curadoria | G9: 1070491 | H9: 9.3 | P9: =IF(G9="","",PERCENTRANK($G$2:$G$85,G9)) -> 0.94 | Q9: =IF(J9="","",1-(J9-1)/20) | R9: =IF(M9="","",1-(M9-1)/(2*N9)) | S9: =IF(K9="","",0.5+0.5*PERCENTRANK($K$2:$K$85,K9)) | T9: =IF(COUNT(Q9:S9)=0,"",MAX(Q9:S9)) | U9: =COUNT(P9,T9) -> 1 | Z9: =COUNTA(V9:Y9) -> 0 | AA9: =IF(U9=0,"",MIN(1,AVERAGE(P9,T9)+Critérios!$B$5*Z9)) -> 0.94 | AB9: =IF(AA9="","",IF(AA9>=Critérios!$B$7,"A",IF(AA9>=Critérios!$B$8,"B","C"))) -> A | AC9: =IF(AA9="","",RANK(AA9,$AA$2:$AA$85)) -> 8 | AD9: =IF(AA9="","Sairia — sem métrica",IF(PERCENTRANK($AA$2:$AA$85,AA9)<Critérios!$B$6,"Sairia — terço inferior","Fica")) -> Fica | AE9: a avaliar | AF9: Evento real | AG9: Resgatada manualmente (lista aprovada em 13/10/2026); conferir ano e título no Brasil | AH9: candidato | AK9: tt7366338 | AL9: =COUNT(G9)+IF(OR(I9<>"",K9<>""),1,0)+IF(M9<>"",1,0)+COUNTA(V9:Y9) -> 1 | AM9: =IF(AL9>=3,"Sim","Não") -> Não | AN9: =IF(AND(AC9<>"",AC9<=Critérios!$B$9),"Sim","Não") -> Sim
A10: S0009 | B10: The Last of Us | C10: The Last of Us | D10: 2023 | E10: HBO | F10: Audiência oficial (coleta) | G10: 753398 | H10: 8.4 | K10: 37000000 | P10: =IF(G10="","",PERCENTRANK($G$2:$G$85,G10)) -> 0.819 | Q10: =IF(J10="","",1-(J10-1)/20) | R10: =IF(M10="","",1-(M10-1)/(2*N10)) | S10: =IF(K10="","",0.5+0.5*PERCENTRANK($K$2:$K$85,K10)) -> 1 | T10: =IF(COUNT(Q10:S10)=0,"",MAX(Q10:S10)) -> 1 | U10: =COUNT(P10,T10) -> 2 | W10: 09 fev–09 mar 2023 #1 | Z10: =COUNTA(V10:Y10) -> 1 | AA10: =IF(U10=0,"",MIN(1,AVERAGE(P10,T10)+Critérios!$B$5*Z10)) -> 0.9395 | AB10: =IF(AA10="","",IF(AA10>=Critérios!$B$7,"A",IF(AA10>=Critérios!$B$8,"B","C"))) -> A | AC10: =IF(AA10="","",RANK(AA10,$AA$2:$AA$85)) -> 9 | AD10: =IF(AA10="","Sairia — sem métrica",IF(PERCENTRANK($AA$2:$AA$85,AA10)<Critérios!$B$6,"Sairia — terço inferior","Fica")) -> Fica | AE10: dupla | AH10: candidato | AJ10: S026 | AK10: tt3581920 | AL10: =COUNT(G10)+IF(OR(I10<>"",K10<>""),1,0)+IF(M10<>"",1,0)+COUNTA(V10:Y10) -> 3 | AM10: =IF(AL10>=3,"Sim","Não") -> Sim | AN10: =IF(AND(AC10<>"",AC10<=Critérios!$B$9),"Sim","Não") -> Sim
A11: S0010 | B11: The Mandalorian | C11: The Mandalorian | D11: 2019 | E11: Disney+ | F11: Audiência oficial (coleta) | G11: 667949 | H11: 8.6 | M11: 5 | N11: 30 | O11: 2020 #13; 2020 #5; 2023 #8 | P11: =IF(G11="","",PERCENTRANK($G$2:$G$85,G11)) -> 0.735 | Q11: =IF(J11="","",1-(J11-1)/20) | R11: =IF(M11="","",1-(M11-1)/(2*N11)) -> 0.93333333 | S11: =IF(K11="","",0.5+0.5*PERCENTRANK($K$2:$K$85,K11)) | T11: =IF(COUNT(Q11:S11)=0,"",MAX(Q11:S11)) -> 0.93333333 | U11: =COUNT(P11,T11) -> 2 | W11: 2020 (ano); nov 2020–jan 2021; 09 fev–09 mar 2023 #3 | X11: 2020 (ano) #1 (United States); 1 jan–30 nov 2023 #1 (United States) | Z11: =COUNTA(V11:Y11) -> 2 | AA11: =IF(U11=0,"",MIN(1,AVERAGE(P11,T11)+Critérios!$B$5*Z11)) -> 0.89416667 | AB11: =IF(AA11="","",IF(AA11>=Critérios!$B$7,"A",IF(AA11>=Critérios!$B$8,"B","C"))) -> A | AC11: =IF(AA11="","",RANK(AA11,$AA$2:$AA$85)) -> 10 | AD11: =IF(AA11="","Sairia — sem métrica",IF(PERCENTRANK($AA$2:$AA$85,AA11)<Critérios!$B$6,"Sairia — terço inferior","Fica")) -> Fica | AE11: claro | AH11: candidato | AJ11: S027 | AK11: tt8111088 | AL11: =COUNT(G11)+IF(OR(I11<>"",K11<>""),1,0)+IF(M11<>"",1,0)+COUNTA(V11:Y11) -> 4 | AM11: =IF(AL11>=3,"Sim","Não") -> Sim | AN11: =IF(AND(AC11<>"",AC11<=Critérios!$B$9),"Sim","Não") -> Sim
